Workbook

Sheet Template
A1: Heading
B2: Sub Heading | G2: Separation Column
C3: Sub Heading
B4: Width 0.75
D5: Particulars | E5: Constant | F5: Units | H5: Calulations->
B7: 0.0075 | D7: Width 40 | E7: 12 | F7: 12

Sheet Historicals
A1: Alkem Laboratories Limited
A2: Historical Financial Information
A4: Income Satement | H4: 2021 | I4: =H4+1 -> 2022 | J4: =I4+1 -> 2023 | K4: =J4+1 -> 2024 | L4: =K4+1 -> 2025
D5: 1 Income
D6: (a) Revenue from operations | H6: 88650.1 | I6: 106341.9 | J6: 115992.6 | K6: 126675.8 | L6: 129645.2
D7: (b) Other income | H7: 2332.1 | I7: 1626.5 | J7: 2160.8 | K7: 3108.4 | L7: 4937.4
D8: Total Income | H8: 90982.2 | I8: 107968.4 | J8: 118153.4 | K8: 129784.2 | L8: 134582.6
D9: 2 Expenses
D10: (a) Cost of materials consumed | H10: 23945.4 | I10: 32260.6 | J10: 30569.2 | K10: 32945.9 | L10: 34403.7
D11: (b) Purchases of stock-in-trade | H11: 14377.6 | I11: 14897.1 | J11: 13875.5 | K11: 16288.7 | L11: 15140.2
D12: (c) Changes in inventories of finished goods work-in-progress and stock-in-trade | H12: -3338.4 | I12: -5354.8 | J12: 4623.7 | K12: 141.2 | L12: -1901.3
D13: (d) Employee benefits expense | H13: 16210.3 | I13: 19627.1 | J13: 21313.5 | K13: 22010.1 | L13: 24539.2
D14: (e) Finance costs | H14: 589.2 | I14: 523.7 | J14: 1073.6 | K14: 1124.1 | L14: 1217
D15: Depreciation and amortisation expense | H15: 2745.8 | I15: 3039.6 | J15: 3104.2 | K15: 2993 | L15: 3571.6
D16: (g) Other expenses | H16: 18031.3 | I16: 24382.7 | J16: 29516.2 | K16: 32835 | L16: 32341.9
D17: Total expenses | H17: 72561.2 | I17: 89376 | J17: 104075.9 | K17: 108338 | L17: 109312.3
D18: 3 Profit before exceptional Items and tax (1) - (2) | H18: 18421 | I18: 18592.4 | J18: 14077.5 | K18: 21446.2 | L18: 25270.3
D19: 4 Exceptional Items | I19: -149.6 | J19: -1029.8 | K19: -1214.9
D20: 5 Profit before tax (3) + (4) | H20: 18421 | I20: 18442.8 | J20: 13047.7 | K20: 20231.3 | L20: 25270.3
D21: 6 Tax expense
D22: (a) Current tax | H22: 3965.3 | I22: 3619.8 | J22: 2739 | K22: 4222.8 | L22: 5236
D23: (b) Deferred tax charge/(credit) (net) | H23: -1722 | I23: -1980.2 | J23: 240.6 | K23: -2106.1 | L23: -2125.7
D24: Total tax expenses (a + b) | H24: 2243.3 | I24: 1639.6 | J24: 2979.6 | K24: 2116.7 | L24: 3110.3
D25: Share in loss after tax of associate | L25: -6.2
D26: 7 Profit for the year (5) - (6) + (7) | H26: 16177.7 | I26: 16803.2 | J26: 10068.1 | K26: 18114.6 | L26: 22153.8
D27: 8 Profit attributable to Non-Controlling Interest | H27: 327.5 | I27: 347 | J27: 226.4 | K27: 156.9 | L27: 499
D28: 9 Profit attributable to Owners of the Company (7) - (8) | H28: 15850.2 | I28: 16456.2 | J28: 9841.7 | K28: 17957.7 | L28: 21654.8
D29: 10 Other Comprehensive Income
D30: (a) (i) Items that will not be reclassified subsequently to profit or loss | H30: -89.2 | I30: -90.9 | J30: -48.7 | K30: -93.4 | L30: -218.1
D31: (ii) Income tax relating to items that will not be reclassified to profit or loss | H31: 29.9 | I31: 33.2 | J31: 16.1 | K31: 29.8 | L31: 72.1
D32: (b) (i) Items that will be reclassified to profit or loss | H32: -283.7 | I32: 399.1 | J32: 1181.6 | K32: 264 | L32: 343.2
D33: (ii) Income tax relating to items that will be reclassified to profit or loss | J33: 0 | K33: 0 | L33: 0
D34: Total of Other Comprehensive Income/(Loss) for the year net of tax | H34: -343 | I34: 341.4 | J34: 1149 | K34: 200.4 | L34: 197.2
D35: 11 Other Comprehensive Income/(Loss) attributable to Non-Controlling Interest | H35: -3.4 | I35: -4.1 | J35: -4.1 | K35: -6.1 | L35: -10.3
D36: 12 Other Comprehensive Income/(Loss) attributable to Owners of the Company (10) - (11) | H36: -339.6 | I36: 345.5 | J36: 1153.1 | K36: 206.5 | L36: 207.5
D37: 13 Total Comprehensive Income for the year (7) + (10) | H37: 15834.7 | I37: 17144.6 | J37: 11217.1 | K37: 18315 | L37: 22351
D38: 15 Total Comprehensive Income/(Loss) attributable to Owners of the Company (13)-(14) | H38: 15510.6 | I38: 16801.7 | J38: 10994.8 | K38: 18164.2 | L38: 21862.3
D39: 14 Total Comprehensive Income/(Loss) attributable to Non-Controlling Interest (8) + (11) | H39: 324.1 | I39: 342.9 | J39: 222.3 | K39: 150.8 | L39: 488.7
D40: 16 Earnings per share (In ): Face value of * 2 each
D41: Basic and diluted earnings per share | H41: 132.57 | I41: 137.63 | J41: 82.31 | K41: 150.19 | L41: 181.11
...

Sheet Model
A1: =Historicals!A1 -> Alkem Laboratories Limited | H1: Historical Period | M1: Forcasted Period
A2: Finanicial Statements and Analysis | H2: 2021 | I2: =H2+1 -> 2022 | J2: =I2+1 -> 2023 | K2: =J2+1 -> 2024 | L2: =K2+1 -> 2025 | M2: =L2+1 -> 2026 | N2: =M2+1 -> 2027 | O2: =N2+1 -> 2028 | P2: =O2+1 -> 2029 | Q2: =P2+1 -> 2030
A4: Ratios & Assumptions
D6: Live Scenario | E6: Base Case | F6: Units
D7: Revenue(Growth) | F7: % | I7: =(I24-H24)/H24 -> 0.19956887 | J7: =(J24-I24)/I24 -> 0.090751623 | K7: =(K24-J24)/J24 -> 0.092102427 | L7: =(L24-K24)/K24 -> 0.023440941 | M7: {=_xlfn.XLOOKUP($E$6, Scenarios!D5:D7,Scenarios!H5:L7,,0)} -> 0.1 | N7: 0.089 | O7: 0.07921 | P7: 0.0704969 | Q7: 0.062742241
D8: Cost of Goood Sold (% of Revenue) | F8: % | H8: =-H25/H24 -> 0.39463689 | I8: =-I25/I24 -> 0.39309905 | J8: =-J25/J24 -> 0.42303043 | K8: =-K25/K24 -> 0.38978084 | L8: =-L25/L24 -> 0.36748449 | M8: =AVERAGE($I8:$L8) -> 0.3933487 | N8: =AVERAGE($I8:$L8) -> 0.3933487 | O8: =AVERAGE($I8:$L8) -> 0.3933487 | P8: =AVERAGE($I8:$L8) -> 0.3933487 | Q8: =AVERAGE($I8:$L8) -> 0.3933487
D9: Salaries and Benefits (% of Revenue) | F9: % | H9: =-H28/H24 -> 0.1828571 | I9: =-I28/I24 -> 0.18456601 | J9: =-J28/J24 -> 0.18374879 | K9: =-K28/K24 -> 0.17375142 | L9: =-L28/L24 -> 0.18927966 | M9: =AVERAGE($I9:$L9) -> 0.18283647 | N9: =AVERAGE($I9:$L9) -> 0.18283647 | O9: =AVERAGE($I9:$L9) -> 0.18283647 | P9: =AVERAGE($I9:$L9) -> 0.18283647 | Q9: =AVERAGE($I9:$L9) -> 0.18283647
D10: Other SG&A Expenses (% of Revenue) | F10: % | H10: =-H29/H24 -> 0.20339853 | I10: =-I29/I24 -> 0.22928592 | J10: =-J29/J24 -> 0.25446623 | K10: =-K29/K24 -> 0.25920499 | L10: =-L29/L24 -> 0.24946469 | M10: =AVERAGE($I10:$L10) -> 0.24810546 | N10: =AVERAGE($I10:$L10) -> 0.24810546 | O10: =AVERAGE($I10:$L10) -> 0.24810546 | P10: =AVERAGE($I10:$L10) -> 0.24810546 | Q10: =AVERAGE($I10:$L10) -> 0.24810546
D11: Depreciation and amortisation expense (% of PP&E) | F11: % | I11: =-I31/H51 -> 0.10891227 | J11: =-J31/I51 -> 0.10937522 | K11: =-K31/J51 -> 0.11542971 | L11: =-L31/K51 -> 0.13660163 | M11: =AVERAGE($I11:$L11) -> 0.11757971 | N11: =AVERAGE($I11:$L11) -> 0.11757971 | O11: =AVERAGE($I11:$L11) -> 0.11757971 | P11: =AVERAGE($I11:$L11) -> 0.11757971 | Q11: =AVERAGE($I11:$L11) -> 0.11757971
D12: Interest Expenses (% of Debt) | F12: % | I12: =-I33/H62 -> 0.029224657 | J12: =-J33/I62 -> 0.040237015 | K12: =-K33/J62 -> 0.080483719 | L12: =-L33/K62 -> 0.085800298 | M12: =AVERAGE($I12:$L12) -> 0.058936422 | N12: =AVERAGE($I12:$L12) -> 0.058936422 | O12: =AVERAGE($I12:$L12) -> 0.058936422 | P12: =AVERAGE($I12:$L12) -> 0.058936422 | Q12: =AVERAGE($I12:$L12) -> 0.058936422
D13: Other Income(Expenses) (% of Revenue) | F13: % | H13: =H34/H24 -> 0.026306795 | I13: =I34/I24 -> 0.013888223 | J13: =J34/J24 -> 0.009750622 | K13: =K34/K24 -> 0.014947606 | L13: =L34/L24 -> 0.03808394 | M13: =AVERAGE($I13:$L13) -> 0.019167598 | N13: =AVERAGE($I13:$L13) -> 0.019167598 | O13: =AVERAGE($I13:$L13) -> 0.019167598 | P13: =AVERAGE($I13:$L13) -> 0.019167598 | Q13: =AVERAGE($I13:$L13) -> 0.019167598
D14: Taxes (% of Earnings before Tax) | F14: % | H14: =-H36/H35 -> 0.12177949 | I14: =-I36/I35 -> 0.088901902 | J14: =-J36/J35 -> 0.22836209 | K14: =-K36/K35 -> 0.10462501 | L14: =-L36/L35 -> 0.12308125 | M14: =AVERAGE($I14:$L14) -> 0.13624256 | N14: =AVERAGE($I14:$L14) -> 0.13624256 | O14: =AVERAGE($I14:$L14) -> 0.13624256 | P14: =AVERAGE($I14:$L14) -> 0.13624256 | Q14: =AVERAGE($I14:$L14) -> 0.13624256
D15: Dividend Payout | F15: % | H15: =-H96/H37 -> 0.20693918 | I15: =-I96/I37 -> 0.25108908 | J15: =-J96/J37 -> 0.52593836 | K15: =-K96/K37 -> 0.29837258 | L15: =-L96/L37 -> 0.22771661 | M15: =AVERAGE($I15:$L15) -> 0.32577916 | N15: =AVERAGE($I15:$L15) -> 0.32577916 | O15: =AVERAGE($I15:$L15) -> 0.32577916 | P15: =AVERAGE($I15:$L15) -> 0.32577916 | Q15: =AVERAGE($I15:$L15) -> 0.32577916
D16: Accounts Recievables | F16: Days | H16: =(H46/H24)*365 -> 66.173828 | I16: =(I46/I24)*365 -> 64.685604 | J16: =(J46/J24)*365 -> 67.094427 | K16: =(K46/K24)*365 -> 64.911818 | L16: =(L46/L24)*365 -> 69.434214 | M16: =AVERAGE($I16:$L16) -> 66.531516 | N16: =AVERAGE($I16:$L16) -> 66.531516 | O16: =AVERAGE($I16:$L16) -> 66.531516 | P16: =AVERAGE($I16:$L16) -> 66.531516 | Q16: =AVERAGE($I16:$L16) -> 66.531516
D17: Inventory DIO | F17: Days | H17: =(-H47/H25)*365 -> 241.26061 | I17: =(-I47/I25)*365 -> 262.4264 | J17: =(-J47/J25)*365 -> 193.96362 | K17: =(-K47/K25)*365 -> 196.72202 | L17: =(-L47/L25)*365 -> 223.89199 | M17: =AVERAGE($I17:$L17) -> 219.25101 | N17: =AVERAGE($I17:$L17) -> 219.25101 | O17: =AVERAGE($I17:$L17) -> 219.25101 | P17: =AVERAGE($I17:$L17) -> 219.25101 | Q17: =AVERAGE($I17:$L17) -> 219.25101
D18: Accounts Payables | F18: Days | H18: =-(H59/H25)*365 -> 111.57328 | I18: =-(I59/I25)*365 -> 102.45311 | J18: =-(J59/J25)*365 -> 86.661874 | K18: =-(K59/K25)*365 -> 129.22602 | L18: =-(L59/L25)*365 -> 140.91648 | M18: =AVERAGE($I18:$L18) -> 114.81437 | N18: =AVERAGE($I18:$L18) -> 114.81437 | O18: =AVERAGE($I18:$L18) -> 114.81437 | P18: =AVERAGE($I18:$L18) -> 114.81437 | Q18: =AVERAGE($I18:$L18) -> 114.81437
D19: Captal asset turnover ratio | F19: Times | H19: =H24/H51 -> 3.1764324 | I19: =I24/I51 -> 3.7469134 | J19: =J24/J51 -> 4.4734354 | K19: =K24/K51 -> 4.8449214 | L19: =L24/L51 -> 4.3544993 | M19: =AVERAGE($I19:$L19) -> 4.3549424 | N19: =AVERAGE($I19:$L19) -> 4.3549424 | O19: =AVERAGE($I19:$L19) -> 4.3549424 | P19: =AVERAGE($I19:$L19) -> 4.3549424 | Q19: =AVERAGE($I19:$L19) -> 4.3549424
A22: Income Statement
B23: Income
D24: Revenue | F24: ₹ in MM | H24: {=Historicals!H6:L6} -> 88650.1 | I24: 106341.9 | J24: 115992.6 | K24: 126675.8 | L24: 129645.2 | M24: =L24*(1+M7) -> 142609.72 | N24: =M24*(1+N7) -> 155301.99 | O24: =N24*(1+O7) -> 167603.46 | P24: =O24*(1+P7) -> 179418.98 | Q24: =P24*(1+Q7) -> 190676.13
D25: Cost of Goood Sold(COGS) | F25: ₹ in MM | H25: =-SUM(Historicals!H10:H12) -> -34984.6 | I25: =-SUM(Historicals!I10:I12) -> -41802.9 | J25: =-SUM(Historicals!J10:J12) -> -49068.4 | K25: =-SUM(Historicals!K10:K12) -> -49375.8 | L25: =-SUM(Historicals!L10:L12) -> -47642.6 | M25: =-M24*M8 -> -56095.349 | N25: =-N24*N8 -> -61087.835 | O25: =-O24*O8 -> -65926.602 | P25: =-P24*P8 -> -70574.223 | Q25: =-Q24*Q8 -> -75002.208
D26: Gross Profit | F26: ₹ in MM | H26: =SUM(H24:H25) -> 53665.5 | I26: =SUM(I24:I25) -> 64539 | J26: =SUM(J24:J25) -> 66924.2 | K26: =SUM(K24:K25) -> 77300 | L26: =SUM(L24:L25) -> 82002.6 | M26: =M25+M24 -> 86514.371 | N26: =N25+N24 -> 94214.15 | O26: =O25+O24 -> 101676.85 | P26: =P25+P24 -> 108844.76 | Q26: =Q25+Q24 -> 115673.92
C27: Expense
D28: Salalries and Benefits | F28: ₹ in MM | H28: {=-Historicals!H13:L13} -> -16210.3 | I28: -19627.1 | J28: -21313.5 | K28: -22010.1 | L28: -24539.2 | M28: =-M24*M9 -> -26074.258 | N28: =-N24*N9 -> -28394.867 | O28: =-O24*O9 -> -30644.024 | P28: =-P24*P9 -> -32804.333 | Q28: =-Q24*Q9 -> -34862.55
D29: Other SG&A Expenses | F29: ₹ in MM | H29: {=-Historicals!H16:L16} -> -18031.3 | I29: -24382.7 | J29: -29516.2 | K29: -32835 | L29: -32341.9 | M29: =-M24*M10 -> -35382.25 | N29: =-N24*N10 -> -38531.27 | O29: =-O24*O10 -> -41583.332 | P29: =-P24*P10 -> -44514.828 | Q29: =-Q24*Q10 -> -47307.788
D30: EBITDA | F30: ₹ in MM | H30: =SUM(H26:H29) -> 19423.9 | I30: =SUM(I26:I29) -> 20529.2 | J30: =SUM(J26:J29) -> 16094.5 | K30: =SUM(K26:K29) -> 22454.9 | L30: =SUM(L26:L29) -> 25121.5 | M30: =SUM(M26:M29) -> 25057.863 | N30: =SUM(N26:N29) -> 27288.013 | O30: =SUM(O26:O29) -> 29449.497 | ... Q30: =SUM(Q26:Q29) -> 33503.582
D31: =Historicals!D15 -> Depreciation and amortisation expense | F31: ₹ in MM | H31: {=-Historicals!H15:L15} -> -2745.8 | I31: -3039.6 | J31: -3104.2 | K31: -2993 | L31: -3571.6 | M31: =M115 -> -3500.6654 | N31: =N115 -> -3439.0891 | O31: =O115 -> -3377.4023 | P31: =P115 -> -3312.4175 | Q31: =Q115 -> -3241.9534
D32: EBIT | F32: ₹ in MM | H32: =SUM(H30:H31) -> 16678.1 | I32: =SUM(I30:I31) -> 17489.6 | J32: =SUM(J30:J31) -> 12990.3 | K32: =SUM(K30:K31) -> 19461.9 | L32: =SUM(L30:L31) -> 21549.9 | M32: =SUM(M30:M31) -> 21557.198 | N32: =SUM(N30:N31) -> 23848.924 | O32: =SUM(O30:O31) -> 26072.095 | ... Q32: =SUM(Q30:Q31) -> 30261.628
D33: Interest Expenses | F33: ₹ in MM | H33: {=-Historicals!H14:L14} -> -589.2 | I33: -523.7 | J33: -1073.6 | K33: -1124.1 | L33: -1217 | M33: =M122 -> -813.85305 | N33: =N122 -> -813.85305 | O33: =O122 -> -813.85305 | P33: =P122 -> -813.85305 | Q33: =Q122 -> -813.85305
D34: Other Income | F34: ₹ in MM | H34: =Historicals!H7+Historicals!H19 -> 2332.1 | I34: =Historicals!I7+Historicals!I19 -> 1476.9 | J34: =Historicals!J7+Historicals!J19 -> 1131 | K34: =Historicals!K7+Historicals!K19 -> 1893.5 | L34: =Historicals!L7+Historicals!L19 -> 4937.4 | M34: =M13*M24 -> 2733.4858 | N34: =N13*N24 -> 2976.766 | O34: =O13*O24 -> 3212.5556 | P34: =P13*P24 -> 3439.0308 | Q34: =Q13*Q24 -> 3654.8033
D35: Earnings Before Tax | F35: ₹ in MM | H35: =SUM(H32:H34) -> 18421 | I35: =SUM(I32:I34) -> 18442.8 | J35: =SUM(J32:J34) -> 13047.7 | K35: =SUM(K32:K34) -> 20231.3 | L35: =SUM(L32:L34) -> 25270.3 | M35: =SUM(M32:M34) -> 23476.831 | N35: =SUM(N32:N34) -> 26011.837 | O35: =SUM(O32:O34) -> 28470.797 | ... Q35: =SUM(Q32:Q34) -> 33102.578
D36: Taxes | F36: ₹ in MM | H36: {=-Historicals!H24:L24} -> -2243.3 | I36: -1639.6 | J36: -2979.6 | K36: -2116.7 | L36: -3110.3 | M36: =M14*-M35 -> -3198.5436 | N36: =N14*-N35 -> -3543.9193 | O36: =O14*-O35 -> -3878.9343 | P36: =P14*-P35 -> -4201.4965 | Q36: =Q14*-Q35 -> -4509.9801
D37: Net Earnings | F37: ₹ in MM | H37: =SUM(H35:H36) -> 16177.7 | I37: =SUM(I35:I36) -> 16803.2 | J37: =SUM(J35:J36) -> 10068.1 | K37: =SUM(K35:K36) -> 18114.6 | L37: =SUM(L35:L36) -> 22160 | M37: =SUM(M35:M36) -> 20278.287 | N37: =SUM(N35:N36) -> 22467.918 | O37: =SUM(O35:O36) -> 24591.863 | ... Q37: =SUM(Q35:Q36) -> 28592.598
A40: Balance Sheet
B42: Assets
C43: Current Assets
D44: Cash | F44: ₹ in MM | H44: {=Historicals!H66:L66} -> 1742.2 | I44: 2321.8 | J44: 2738 | K44: 4550.7 | L44: 3041.4 | M44: =M101 -> 10685.173 | N44: =N101 -> 22616.139 | O44: =O101 -> 36122.378 | P44: =P101 -> 51197.266 | Q44: =Q101 -> 67813.13
D45: Bank Deposits | F45: ₹ in MM | H45: {=Historicals!H67:L67} -> 18162.3 | I45: 23464 | J45: 23430.9 | K45: 11242.8 | L45: 12589.4 | M45: =L45 -> 12589.4 | N45: =M45 -> 12589.4 | O45: =N45 -> 12589.4 | P45: =O45 -> 12589.4 | Q45: =P45 -> 12589.4
D46: Accounts Receivables | F46: ₹ in MM | H46: {=Historicals!H65:L65} -> 16072.1 | I46: 18846 | J46: 21321.8 | K46: 22528.1 | L46: 24662.5 | M46: =M16*M24/365 -> 25994.632 | N46: =N16*N24/365 -> 28308.155 | O46: =O16*O24/365 -> 30550.444 | P46: =P16*P24/365 -> 32704.155 | Q46: =Q16*Q24/365 -> 34756.087
D47: Inventory | F47: ₹ in MM | H47: {=Historicals!H62:L62} -> 23124.4 | I47: 30055.3 | J47: 26075.3 | K47: 26611.8 | L47: 29224.1 | M47: =-M17*M25/365 -> 33695.785 | N47: =-N17*N25/365 -> 36694.71 | O47: =-O17*O25/365 -> 39601.298 | P47: =-P17*P25/365 -> 42393.067 | Q47: =-Q17*Q25/365 -> 45052.903
...

Sheet Scenarios
A1: Alkem Laboratories Limited
A2: Scenarios
C4: Scenarios | E4: Growth | H4: 2026 | I4: =H4+1 -> 2027 | J4: =I4+1 -> 2028 | K4: =J4+1 -> 2029 | L4: =K4+1 -> 2030
D5: Base Case | E5: =Historicals!L166 -> 0.1 | H5: {=E5:E7} -> 0.1 | I5: =H5*(1-$E$8) -> 0.089 | J5: =I5*(1-$E$8) -> 0.07921 | K5: =J5*(1-$E$8) -> 0.0704969 | L5: =K5*(1-$E$8) -> 0.062742241
D6: Bull Case | E6: =MAX(Model!I7:L7) -> 0.19956887 | H6: 0.19956887 | I6: =H6*(1-$E$8) -> 0.17761629 | J6: =I6*(1-$E$8) -> 0.1580785 | K6: =J6*(1-$E$8) -> 0.14068986 | L6: =K6*(1-$E$8) -> 0.12521398
D7: Bear Case | E7: 0.074 | H7: 0.074 | I7: =H7*(1-$E$8) -> 0.06586 | J7: =I7*(1-$E$8) -> 0.0586154 | K7: =J7*(1-$E$8) -> 0.052167706 | L7: =K7*(1-$E$8) -> 0.046429258
D8: Annual Growth Tapering | E8: 0.11
D16: Base Case Is Compund annual growth rate of 4 years
D17: Bull Case is maximum rate of previous 4 years revenue growth
D18: Bear Case is economic growth rate
D19: Also Indian Pharmaceutical sector is expected to grow at a CAGR of 21% so if company can apply full potential towards growth it can achieve this bullish rate

Sheet Comps_Data
A1: S.No. | B1: Name | C1: CMP Rs. | D1: P/E | E1: EV / EBITDA | F1: Mar Cap Rs.MM | G1: No. Eq. Shares PY MM | H1: Debt Rs.MM | I1: Cash Rs.MM | J1: EV Rs.MM | K1: Sales Rs.MM | L1: EBIDT Ann Rs.MM | M1: PAT 12M Rs.MM | N1: Tax In MM | O1: Levered Beta | P1: Tax Rate
A2: 1 | B2: Sun Pharma.Inds. | C2: 1785.7 | D2: 35.31 | E2: 21.48 | F2: 4285464.2 | G2: 2399.3 | H2: 52151 | I2: 122574.2 | J2: 4215041 | K2: 568090.9 | L2: 172531.3 | M2: 121373.1 | N2: 38204.5 | O2: 0.09 | P2: =N2/(M2+N2) -> 0.23941017
A3: 2 | B3: Divi's Lab. | C3: 6474 | D3: 67.82 | E3: 44.02 | F3: 1717945.2 | G3: 265.5 | H3: 900 | I3: 32610 | J3: 1686235.2 | K3: 103140 | L3: 33200 | M3: 25332.7 | N3: 8100 | O3: 0.09 | P3: =N3/(M3+N3) -> 0.24227777
A4: 3 | B4: Torrent Pharma. | C4: 4399.8 | D4: 64.57 | E4: 37.08 | F4: 1488789.1 | G4: 338.4 | H4: 28220 | I4: 7050 | J4: 1509959.1 | K4: 127420 | L4: 37261.9 | M4: 23055.3 | N4: 7360 | O4: 0.13 | P4: =N4/(M4+N4) -> 0.24198348
A5: 4 | B5: Dr Reddy's Labs | C5: 1319.3 | D5: 19.77 | E5: 12.01 | F5: 1101060.3 | G5: 834.1 | H5: 58540 | I5: 20464 | J5: 1139136.3 | K5: 346822 | L5: 95149 | M5: 55684 | N5: 14761.7 | O5: 0.29 | P5: =N5/(M5+N5) -> 0.20954721
A6: 5 | B6: Cipla | C6: 1358.1 | D6: 23.08 | E6: 14.61 | F6: 1097373.1 | G6: 807.4 | H6: 4673.7 | I6: 7958.5 | J6: 1094088.3 | K6: 283510.8 | L6: 78205.6 | M6: 47548.2 | N6: 16752 | O6: -0.05 | P6: =N6/(M6+N6) -> 0.26052796
A7: 6 | B7: Lupin | C7: 2323.2 | D7: 21.34 | E7: 13.68 | F7: 1061687 | G7: 455.7 | H7: 62170 | I7: 30402.2 | J7: 1093454.8 | K7: 261505 | L7: 54336.4 | M7: 49744.8 | N7: 11712.1 | O7: 0.3 | P7: =N7/(M7+N7) -> 0.19057421
A8: 7 | B8: Zydus Lifesci. | C8: 938.5 | D8: 18.49 | E8: 11.92 | F8: 944607.4 | G8: 1006.2 | H8: 96361 | I8: 27825 | J8: 1013143.4 | K8: 260893 | L8: 72935 | M8: 51081.9 | N8: 3812.7 | O8: 0.37 | P8: =N8/(M8+N8) -> 0.069454919
A9: 8 | B9: Alkem Lab | C9: 5752 | D9: 28.69 | E9: 20.44 | F9: 688613.2 | G9: 119.6 | H9: 23556 | I9: 15476.5 | J9: 696692.7 | K9: 142527 | L9: 30012.9 | M9: 24004.6 | N9: 4199.2 | O9: 0.3 | P9: =N9/(M9+N9) -> 0.14888774
C14: Levered Beta | D14: Unlevered Beta
B15: SUNPHARMA.NS | C15: 0.73014229 | D15: 0.61485667 | F15: Calculated this beta using python model , screener and yahoo finance beta was not reliable
B16: DRREDDY.NS | C16: 0.28589585 | D16: 0.2407544
B17: CIPLA.NS | C17: 0.46513529 | D17: 0.39169288
B18: LUPIN.NS | C18: 0.7100613 | D18: 0.59794636
B19: ALKEM.NS | C19: 0.57148874 | D19: 0.48125368
B20: DIVISLAB.NS | C20: 0.51245306 | D20: 0.43153942
B21: ZYDUSLIFE.NS | C21: 0.4711077 | D21: 0.39672227
B22: AUROPHARMA.NS | C22: 0.94568223 | D22: 0.79636399
B23: TORNTPHARM.NS | C23: 0.49695289 | D23: 0.41848664
B24: BIOCON.NS | C24: 0.73299902 | D24: 0.61726233
B25: GLENMARK.NS | C25: 1.1667611 | D25: 0.98253566
B26: IPCALAB.NS | C26: 0.38094756 | D26: 0.32079794
B27: LAURUSLABS.NS | C27: 1.4498065 | D27: 1.2208897
... B29: GRANULES.NS | C29: 0.64538035 | D29: 0.54347819
B31: Average | C31: =AVERAGE(C15:C29) -> 0.65224175 | D31: =AVERAGE(D15:D29) -> 0.54925621
B32: Median | C32: =MEDIAN(C15:C29) -> 0.57148874 | D32: =MEDIAN(D15:D29) -> 0.48125368

Sheet Comps
A1: Alkem Laboratories Limited
A2: Comps Valuation
H5: Market Data | O5: Financial Data | S5: Valuation Metrics
H6: Price | I6: Shares | J6: Market Cap | K6: Debt | L6: Cash | M6: EV | O6: Sale | P6: EBITDA | Q6: Earnings | S6: EV/Sales | T6: EV/EBITDA | U6: P/E
D7: Company Name | H7: ₹/share | I7: M | J7: ₹ MM | K7: ₹ MM | L7: ₹ MM | M7: ₹ MM | O7: ₹ MM | P7: ₹ MM | Q7: ₹ MM | S7: x | T7: x | U7: x
D8: {=Comps_Data!B2:B9} -> Sun Pharma.Inds. | H8: {=Comps_Data!C2:C9} -> 1785.7 | I8: {=Comps_Data!G2:G9} -> 2399.3 | J8: =H8*I8 -> 4284430 | K8: {=Comps_Data!H2:H9} -> 52151 | L8: {=Comps_Data!I2:I9} -> 122574.2 | M8: =J8+K8-L8 -> 4214006.8 | O8: {=Comps_Data!K2:K9} -> 568090.9 | P8: {=Comps_Data!L2:L9} -> 172531.3 | Q8: {=Comps_Data!M2:M9} -> 121373.1 | S8: =M8/O8 -> 7.417839 | T8: =M8/P8 -> 24.424593 | U8: =J8/Q8 -> 35.299667
D9: Divi's Lab. | H9: 6474 | I9: 265.5 | J9: =H9*I9 -> 1718847 | K9: 900 | L9: 32610 | M9: =J9+K9-L9 -> 1687137 | O9: 103140 | P9: 33200 | Q9: 25332.7 | S9: =M9/O9 -> 16.357737 | T9: =M9/P9 -> 50.81738 | U9: =J9/Q9 -> 67.85092
D10: Torrent Pharma. | H10: 4399.8 | I10: 338.4 | J10: =H10*I10 -> 1488892.3 | K10: 28220 | L10: 7050 | M10: =J10+K10-L10 -> 1510062.3 | O10: 127420 | P10: 37261.9 | Q10: 23055.3 | S10: =M10/O10 -> 11.851062 | T10: =M10/P10 -> 40.525639 | U10: =J10/Q10 -> 64.579178
D11: Dr Reddy's Labs | H11: 1319.3 | I11: 834.1 | J11: =H11*I11 -> 1100428.1 | K11: 58540 | L11: 20464 | M11: =J11+K11-L11 -> 1138504.1 | O11: 346822 | P11: 95149 | Q11: 55684 | S11: =M11/O11 -> 3.2826756 | T11: =M11/P11 -> 11.965487 | U11: =J11/Q11 -> 19.762017
D12: Cipla | H12: 1358.1 | I12: 807.4 | J12: =H12*I12 -> 1096529.9 | K12: 4673.7 | L12: 7958.5 | M12: =J12+K12-L12 -> 1093245.1 | O12: 283510.8 | P12: 78205.6 | Q12: 47548.2 | S12: =M12/O12 -> 3.856097 | T12: =M12/P12 -> 13.979116 | U12: =J12/Q12 -> 23.06144
D13: Lupin | H13: 2323.2 | I13: 455.7 | J13: =H13*I13 -> 1058682.2 | K13: 62170 | L13: 30402.2 | M13: =J13+K13-L13 -> 1090450 | O13: 261505 | P13: 54336.4 | Q13: 49744.8 | S13: =M13/O13 -> 4.1699013 | T13: =M13/P13 -> 20.0685 | U13: =J13/Q13 -> 21.28227
D14: Zydus Lifesci. | H14: 938.5 | I14: 1006.2 | J14: =H14*I14 -> 944318.7 | K14: 96361 | L14: 27825 | M14: =J14+K14-L14 -> 1012854.7 | O14: 260893 | P14: 72935 | Q14: 51081.9 | S14: =M14/O14 -> 3.8822609 | T14: =M14/P14 -> 13.887087 | U14: =J14/Q14 -> 18.486366
D15: Alkem Lab | H15: 5752 | I15: 119.6 | J15: =H15*I15 -> 687939.2 | K15: 23556 | L15: 15476.5 | M15: =J15+K15-L15 -> 696018.7 | O15: 142527 | P15: 30012.9 | Q15: 24004.6 | S15: =M15/O15 -> 4.8834165 | T15: =M15/P15 -> 23.190651 | U15: =J15/Q15 -> 28.65864
D18: Average | S18: =AVERAGE(S8:S15) -> 6.9626237 | T18: =AVERAGE(T8:T15) -> 24.857307 | U18: =AVERAGE(U8:U15) -> 34.872562
D19: Median | S19: =MEDIAN(S8:S15) -> 4.5266589 | T19: =MEDIAN(T8:T15) -> 21.629576 | U19: =MEDIAN(U8:U15) -> 25.86004
D21: =D15 -> Alkem Lab | H21: {=H15:M15} -> 5752 | I21: 119.6 | J21: 687939.2 | K21: 23556 | L21: 15476.5 | M21: 696018.7 | O21: {=O15:Q15} -> 142527 | P21: 30012.9 | Q21: 24004.6 | S21: {=S15:U15} -> 4.8834165 | T21: 23.190651 | U21: 28.65864
D23: Metric | E23: Comps | H23: EV | I23: Net Debt | J23: Equity Value | K23: Shares | L23: Share Price
D24: {=TRANSPOSE(S6:U6)} -> EV/Sales | E24: {=TRANSPOSE(S19:U19)} -> 4.5266589 | H24: =E24*O21 -> 645171.11 | I24: =K21-L21 -> 8079.5 | J24: =H24-I24 -> 637091.61 | K24: =I21 -> 119.6 | L24: =J24/K24 -> 5326.8529
D25: EV/EBITDA | E25: 21.629576 | H25: =E25*P21 -> 649166.29 | I25: =I24 -> 8079.5 | J25: =H25-I25 -> 641086.79 | K25: =K24 -> 119.6 | L25: =J25/K25 -> 5360.2574
D26: P/E | E26: 25.86004 | H26: =SUM(I26:J26) -> 628839.42 | I26: =I25 -> 8079.5 | J26: =E26*Q21 -> 620759.92 | K26: =K25 -> 119.6 | L26: =J26/K26 -> 5190.3003

Sheet WACC
A1: Alkem Laboratories Limited
A2: Weigthed Average Cost of Capital
A5: Comparable Companies Beta
H6: Equity | I6: Total | J6: Debt/ | K6: Debt/ | L6: Tax | M6: Levered | N6: Unlevered
D7: Name | H7: Value | I7: Debt | J7: Equity | K7: Capital | L7: Rate% | M7: Beta | N7: Beta
D8: {=Comps_Data!B2:B8} -> Sun Pharma.Inds. | H8: {=Comps!J8:J14} -> 4284430 | I8: =Comps!K8 -> 52151 | J8: =I8/H8 -> 0.012172214 | K8: =I8/(H8+I81) -> 0.012172214 | L8: {=Comps_Data!P2:P8} -> 0.23941017 | M8: {=Comps_Data!O2:O8} -> 0.09 | N8: =M8/(J8*(1-L8)+1) -> 0.089174418 | O8: These levered betas I got from screeener doesn't make sense, it's too defensive for pharma sector. I checked Damodaran's Beta for pharma (180 companies) which was 0.98 but was dominated by US market so I am estimating indian pharmaceutical sector average levered Beta as 0.57 after regressing companies in python. (Output in Comps_Data)
D9: Divi's Lab. | H9: 1718847 | I9: =Comps!K9 -> 900 | J9: =I9/H9 -> 0.00052360681 | K9: =I9/(H9+I82) -> 0.00052360681 | L9: 0.24227777 | M9: 0.09 | N9: =M9/(J9*(1-L9)+1) -> 0.089964307
D10: Torrent Pharma. | H10: 1488892.3 | I10: =Comps!K10 -> 28220 | J10: =I10/H10 -> 0.018953688 | K10: =I10/(H10+I83) -> 0.018953688 | L10: 0.24198348 | M10: 0.13 | N10: =M10/(J10*(1-L10)+1) -> 0.12815872
D11: Dr Reddy's Labs | H11: 1100428.1 | I11: =Comps!K11 -> 58540 | J11: =I11/H11 -> 0.053197477 | K11: =I11/(H11+I84) -> 0.053197477 | L11: 0.20954721 | M11: 0.29 | N11: =M11/(J11*(1-L11)+1) -> 0.27829756
D12: Cipla | H12: 1096529.9 | I12: =Comps!K12 -> 4673.7 | J12: =I12/H12 -> 0.0042622639 | K12: =I12/(H12+I85) -> 0.0042622639 | L12: 0.26052796 | M12: -0.05 | N12: =M12/(J12*(1-L12)+1) -> -0.049842904
D13: Lupin | H13: 1058682.2 | I13: =Comps!K13 -> 62170 | J13: =I13/H13 -> 0.058723947 | K13: =I13/(H13+I86) -> 0.058723947 | L13: 0.19057421 | M13: 0.3 | N13: =M13/(J13*(1-L13)+1) -> 0.28638725
D14: Zydus Lifesci. | H14: 944318.7 | I14: =Comps!K14 -> 96361 | J14: =I14/H14 -> 0.10204288 | K14: =I14/(H14+I87) -> 0.10204288 | L14: 0.069454919 | M14: 0.37 | N14: =M14/(J14*(1-L14)+1) -> 0.33791328
D16: Average | H16: =AVERAGE(_xlfn.ANCHORARRAY(H8)) -> 1670304 | I16: =AVERAGE(I8:I14) -> 43287.957 | J16: =AVERAGE(J8:J14) -> 0.035696582 | K16: =AVERAGE(K8:K14) -> 0.035696582 | L16: =AVERAGE(_xlfn.ANCHORARRAY(L8)) -> 0.20768224 | M16: =Comps_Data!C31 -> 0.65224175 | N16: =Comps_Data!D31 -> 0.54925621
D17: Median | H17: =MEDIAN(_xlfn.ANCHORARRAY(H8)) -> 1100428.1 | I17: =MEDIAN(I8:I14) -> 52151 | J17: =MEDIAN(J8:J14) -> 0.018953688 | K17: =MEDIAN(K8:K14) -> 0.018953688 | L17: =MEDIAN(L8:L14) -> 0.23941017 | M17: =Comps_Data!C32 -> 0.57148874 | N17: =Comps_Data!D32 -> 0.48125368
D19: Alkem Lab | H19: 687939.2 | I19: 23556 | J19: 0.034241398 | K19: 0.034241398 | L19: 0.14888774
A21: WACC Calculation
C23: Target Capital Structure
D25: Proportion of Debt | H25: =K16 -> 0.035696582
D26: Proportion Of Equity | H26: =1-H25 -> 0.96430342
C28: Current Capital Structure
D29: Market Cap | H29: =H19 -> 687939.2
D30: Total Debt | H30: =I19 -> 23556
D31: Debt/ Equity | H31: =J19 -> 0.034241398
C33: Cost of Debt
D34: Pre Tax Cost of Debt | H34: =Model!M12 -> 0.058936422
D35: Tax Rate | H35: =Model!M14 -> 0.13624256
D36: After Tax Cost of Debt | H36: =H34*(1-H35) -> 0.050906773
C38: Cost of Equity
D39: Risk Free Rate | H39: 0.0665
D40: Equity Market Return | H40: ='Market Data'!E7 -> 0.1374445
D41: Equity Risk Premium | H41: =H40-H39 -> 0.0709445
D42: Levered Equity Beta | H42: =N17*(1+H31*(1-H35)) -> 0.49548736
D43: Cost of Equity | H43: =H39+H41*H42 -> 0.1016521
D45: WACC | H45: =(H43*H26)+(H36*H25) -> 0.099840669

Sheet Beta
A1: Alkem Laboratories Limited
A2: Company Beta
B3: Index | C3: % Change | D3: Stock | E3: % Change
A4: Date | B4: Closing Price | C4: Monthly | D4: Closing Price | E4: Monthly
A5: 44253 | B5: 14529.15 | D5: 2587.0728
A6: 44256 | B6: 14761.55 | C6: =B6/B5-1 -> 0.015995389 | D6: 2687.104 | E6: =D6/D5-1 -> 0.038665805
A7: 44257 | B7: 14919.1 | C7: =B7/B6-1 -> 0.010672985 | D7: 2770.1223 | E7: =D7/D6-1 -> 0.030895086
A8: 44258 | B8: 15245.6 | C8: =B8/B7-1 -> 0.021884699 | D8: 2701.1697 | E8: =D8/D7-1 -> -0.02489155 | H8: Beta | I8: =SLOPE(E6:E1239,C6:C1239) -> 0.49217341
A9: 44259 | B9: 15080.75 | C9: =B9/B8-1 -> -0.010812931 | D9: 2689.3364 | E9: =D9/D8-1 -> -0.0043807881
A10: 44260 | B10: 14938.1 | C10: =B10/B9-1 -> -0.0094591045 | D10: 2645.333 | E10: =D10/D9-1 -> -0.016362184
A11: 44263 | B11: 14956.2 | C11: =B11/B10-1 -> 0.0012117061 | D11: 2647.5188 | E11: =D11/D10-1 -> 0.00082628199
A12: 44264 | B12: 15098.4 | C12: =B12/B11-1 -> 0.0095077756 | D12: 2634.9255 | E12: =D12/D11-1 -> -0.0047566279
A13: 44265 | B13: 15174.8 | C13: =B13/B12-1 -> 0.0050600999 | D13: 2603.8953 | E13: =D13/D12-1 -> -0.011776528
A14: 44267 | B14: 15030.95 | C14: =B14/B13-1 -> -0.0094795062 | D14: 2635.9714 | E14: =D14/D13-1 -> 0.012318534 | H14: SUMMARY OUTPUT
A15: 44270 | B15: 14929.5 | C15: =B15/B14-1 -> -0.00674942 | D15: 2552.7148 | E15: =D15/D14-1 -> -0.031584785
A16: 44271 | B16: 14910.45 | C16: =B16/B15-1 -> -0.0012759841 | D16: 2525.7229 | E16: =D16/D15-1 -> -0.010573818 | H16: Regression Statistics
A17: 44272 | B17: 14721.3 | C17: =B17/B16-1 -> -0.01268576 | D17: 2501.1082 | E17: =D17/D16-1 -> -0.0097456241 | H17: Multiple R | I17: 0.28701621
A18: 44273 | B18: 14557.85 | C18: =B18/B17-1 -> -0.011102973 | D18: 2499.1594 | E18: =D18/D17-1 -> -0.00077914682 | H18: R Square | I18: 0.082378305
A19: 44274 | B19: 14744 | C19: =B19/B18-1 -> 0.012786943 | D19: 2494.6921 | E19: =D19/D18-1 -> -0.0017875151 | H19: Adjusted R Square | I19: 0.081633482
A20: 44277 | B20: 14736.4 | C20: =B20/B19-1 -> -0.00051543742 | D20: 2490.606 | E20: =D20/D19-1 -> -0.0016379503 | H20: Standard Error | I20: 0.014061783
A21: 44278 | B21: 14814.75 | C21: =B21/B20-1 -> 0.00531674 | D21: 2468.6985 | E21: =D21/D20-1 -> -0.0087960404 | H21: Observations | I21: 1234
A22: 44279 | B22: 14549.4 | C22: =B22/B21-1 -> -0.017911177 | D22: 2447.1245 | E22: =D22/D21-1 -> -0.0087390075
A23: 44280 | B23: 14324.9 | C23: =B23/B22-1 -> -0.015430189 | D23: 2509.4241 | E23: =D23/D22-1 -> 0.025458272 | H23: ANOVA
A24: 44281 | B24: 14507.3 | C24: =B24/B23-1 -> 0.012733032 | D24: 2518.6428 | E24: =D24/D23-1 -> 0.0036736517 | I24: df | J24: SS | K24: MS | L24: F | M24: Significance F
A25: 44285 | B25: 14845.1 | C25: =B25/B24-1 -> 0.023284816 | D25: 2603.7993 | E25: =D25/D24-1 -> 0.033810469 | H25: Regression | I25: 1 | J25: 0.021869591 | K25: 0.021869591 | L25: 110.60121 | M25: 7.863702e-25
A26: 44286 | B26: 14690.7 | C26: =B26/B25-1 -> -0.010400699 | D26: 2632.4551 | E26: =D26/D25-1 -> 0.011005365 | H26: Residual | I26: 1232 | J26: 0.24360796 | K26: 0.00019773374
A27: 44287 | B27: 14867.35 | C27: =B27/B26-1 -> 0.012024574 | D27: 2637.8245 | E27: =D27/D26-1 -> 0.0020396871 | H27: Total | I27: 1233 | J27: 0.26547755
A28: 44291 | B28: 14637.8 | C28: =B28/B27-1 -> -0.015439861 | D28: 2573.1965 | E28: =D28/D27-1 -> -0.024500466
A29: 44292 | B29: 14683.5 | C29: =B29/B28-1 -> 0.0031220672 | D29: 2587.833 | E29: =D29/D28-1 -> 0.0056880516 | I29: Coefficients | J29: Standard Error | K29: t Stat | L29: P-value | M29: Lower 95% | N29: Upper 95% | O29: Lower 95.0% | P29: Upper 95.0%
A30: 44293 | B30: 14819.05 | C30: =B30/B29-1 -> 0.009231437 | D30: 2591.825 | E30: =D30/D29-1 -> 0.0015425815 | H30: Intercept | I30: 0.00049505543 | J30: 0.00040095926 | K30: 1.2346776 | L30: 0.21718594 | M30: -0.0002915831 | N30: 0.0012816939 | O30: -0.0002915831 | P30: 0.0012816939
A31: 44294 | B31: 14873.8 | C31: =B31/B30-1 -> 0.0036945689 | D31: 2572.2461 | E31: =D31/D30-1 -> -0.0075540817 | H31: X Variable 1 | I31: 0.49217341 | J31: 0.046799176 | K31: 10.516711 | L31: 7.863702e-25 | M31: 0.40035851 | N31: 0.58398831 | O31: 0.40035851 | P31: 0.58398831
A32: 44295 | B32: 14834.85 | C32: =B32/B31-1 -> -0.0026187118 | D32: 2691.8555 | E32: =D32/D31-1 -> 0.046499973
A33: 44298 | B33: 14310.8 | C33: =B33/B32-1 -> -0.035325589 | D33: 2609.4072 | E33: =D33/D32-1 -> -0.030628777
A34: 44299 | B34: 14504.8 | C34: =B34/B33-1 -> 0.013556196 | D34: 2615.2998 | E34: =D34/D33-1 -> 0.0022582056
A35: 44301 | B35: 14581.45 | C35: =B35/B34-1 -> 0.0052844846 | D35: 2614.0645 | E35: =D35/D34-1 -> -0.00047235562
A36: 44302 | B36: 14617.85 | C36: =B36/B35-1 -> 0.0024962822 | D36: 2652.4133 | E36: =D36/D35-1 -> 0.014670211
A37: 44305 | B37: 14359.45 | C37: =B37/B36-1 -> -0.017676979 | D37: 2612.781 | E37: =D37/D36-1 -> -0.014941987
A38: 44306 | B38: 14296.4 | C38: =B38/B37-1 -> -0.004390823 | D38: 2604.7502 | E38: =D38/D37-1 -> -0.0030736452
A39: 44308 | B39: 14406.15 | C39: =B39/B38-1 -> 0.0076767576 | D39: 2658.6389 | E39: =D39/D38-1 -> 0.020688614
A40: 44309 | B40: 14341.35 | C40: =B40/B39-1 -> -0.0044981331 | D40: 2640.6758 | E40: =D40/D39-1 -> -0.0067565154
...

Sheet Market Data
A1: Alkem Laboratories Limited
A2: Equity Market Return
B4: Index Close
A5: Date | B5: Price | D5: No. of Years | E5: 10
A6: 42426 | B6: 7029.75 | D6: Index | E6: Nifty 50
A7: 42429 | B7: 6987.0498 | D7: Market Return | E7: =_xlfn.RRI(E5,B6,B2469) -> 0.1374445
A8: 42430 | B8: 7222.2998
A9: 42431 | B9: 7368.8501
A10: 42432 | B10: 7475.6001
A11: 42433 | B11: 7485.3501
A12: 42437 | B12: 7485.2998
A13: 42438 | B13: 7531.7998
A14: 42439 | B14: 7486.1499
A15: 42440 | B15: 7510.2002
A16: 42443 | B16: 7538.75
A17: 42444 | B17: 7460.6001
A18: 42445 | B18: 7498.75
A19: 42446 | B19: 7512.5498
... A2469: 46078 | B2469: 25482.5
